|         23700 |    42105.9297 | Layer 1 | Epoch 389  |
|         23730 |    43685.5078 | Layer 1 | Epoch 390  |
|         23760 |    42625.1367 | Layer 1 | Epoch 390  |
|         23790 |    44786.8203 | Layer 1 | Epoch 391  |
|         23820 |    42195.8867 | Layer 1 | Epoch 391  |
|         23850 |    44041.8984 | Layer 1 | Epoch 391  |
|         23880 |    43046.1328 | Layer 1 | Epoch 392  |
|         23910 |    43098.8359 | Layer 1 | Epoch 392  |
|         23940 |    44460.9922 | Layer 1 | Epoch 393  |
|         23970 |    42529.0938 | Layer 1 | Epoch 393  |
|         24000 |    44411.4258 | Layer 1 | Epoch 394  |
|         24030 |    44298.0703 | Layer 1 | Epoch 394  |
|         24060 |    43448.6484 | Layer 1 | Epoch 395  |
|         24090 |    41582.1523 | Layer 1 | Epoch 395  |
|         24120 |    42306.1797 | Layer 1 | Epoch 396  |
|         24150 |    43848.9727 | Layer 1 | Epoch 396  |
|         24180 |    43722.4297 | Layer 1 | Epoch 397  |
|         24210 |    43391.2891 | Layer 1 | Epoch 397  |
|         24240 |    43749.5352 | Layer 1 | Epoch 398  |
|         24270 |    43433.8828 | Layer 1 | Epoch 398  |
|         24300 |    43324.1172 | Layer 1 | Epoch 399  |
|         24330 |    41216.0117 | Layer 1 | Epoch 399  |
|         24360 |    42695.8438 | Layer 1 | Epoch 400  |
|         24390 |    43519.7344 | Layer 1 | Epoch 400  |



| Training Step | Cross Entropy |  Layer  |   Epoch  |
|---------------|---------------|---------|----------|
|             0 |      987.4544 | Layer 2 | Epoch 1  |
|            30 |        0.9977 | Layer 2 | Epoch 1  |
2017-11-26 17:15:10.586540: W tensorflow/core/framework/op_kernel.cc:1192] Invalid argument: Nan in summary histogram for: pretrain_2/autoencoder_variables/biases2
	 [[Node: pretrain_2/autoencoder_variables/biases2 = HistogramSummary[T=DT_FLOAT, _device="/job:localhost/replica:0/task:0/device:CPU:0"](pretrain_2/autoencoder_variables/biases2/tag, autoencoder_variables/biases2/read/_3307)]]
Traceback (most recent call last):
  File "/usr/local/lib/python3.5/dist-packages/tensorflow/python/client/session.py", line 1323, in _do_call
    return fn(*args)
  File "/usr/local/lib/python3.5/dist-packages/tensorflow/python/client/session.py", line 1302, in _run_fn
    status, run_metadata)
  File "/usr/local/lib/python3.5/dist-packages/tensorflow/python/framework/errors_impl.py", line 473, in __exit__
    c_api.TF_GetCode(self.status.status))
tensorflow.python.framework.errors_impl.InvalidArgumentError: Nan in summary histogram for: pretrain_2/autoencoder_variables/biases2
	 [[Node: pretrain_2/autoencoder_variables/biases2 = HistogramSummary[T=DT_FLOAT, _device="/job:localhost/replica:0/task:0/device:CPU:0"](pretrain_2/autoencoder_variables/biases2/tag, autoencoder_variables/biases2/read/_3307)]]
	 [[Node: pretrain_2/xentropy_loss/mul/_3302 = _Send[T=DT_FLOAT, client_terminated=false, recv_device="/job:localhost/replica:0/task:0/device:CPU:0", send_device="/job:localhost/replica:0/task:0/device:GPU:0", send_device_incarnation=1, tensor_name="edge_48_pretrain_2/xentropy_loss/mul", _device="/job:localhost/replica:0/task:0/device:GPU:0"](pretrain_2/xentropy_loss/mul)]]

During handling of the above exception, another exception occurred:

Traceback (most recent call last):
  File "autoencoder.py", line 496, in <module>
    ae = main_unsupervised()
  File "autoencoder.py", line 358, in main_unsupervised
    summary_str = sess.run(summary_op, feed_dict=feed_dict)
  File "/usr/local/lib/python3.5/dist-packages/tensorflow/python/client/session.py", line 889, in run
    run_metadata_ptr)
  File "/usr/local/lib/python3.5/dist-packages/tensorflow/python/client/session.py", line 1120, in _run
    feed_dict_tensor, options, run_metadata)
  File "/usr/local/lib/python3.5/dist-packages/tensorflow/python/client/session.py", line 1317, in _do_run
    options, run_metadata)
  File "/usr/local/lib/python3.5/dist-packages/tensorflow/python/client/session.py", line 1336, in _do_call
    raise type(e)(node_def, op, message)
tensorflow.python.framework.errors_impl.InvalidArgumentError: Nan in summary histogram for: pretrain_2/autoencoder_variables/biases2
	 [[Node: pretrain_2/autoencoder_variables/biases2 = HistogramSummary[T=DT_FLOAT, _device="/job:localhost/replica:0/task:0/device:CPU:0"](pretrain_2/autoencoder_variables/biases2/tag, autoencoder_variables/biases2/read/_3307)]]
	 [[Node: pretrain_2/xentropy_loss/mul/_3302 = _Send[T=DT_FLOAT, client_terminated=false, recv_device="/job:localhost/replica:0/task:0/device:CPU:0", send_device="/job:localhost/replica:0/task:0/device:GPU:0", send_device_incarnation=1, tensor_name="edge_48_pretrain_2/xentropy_loss/mul", _device="/job:localhost/replica:0/task:0/device:GPU:0"](pretrain_2/xentropy_loss/mul)]]

Caused by op 'pretrain_2/autoencoder_variables/biases2', defined at:
  File "autoencoder.py", line 496, in <module>
    ae = main_unsupervised()
  File "autoencoder.py", line 339, in main_unsupervised
    for v in summary_vars]
  File "autoencoder.py", line 339, in <listcomp>
    for v in summary_vars]
  File "/usr/local/lib/python3.5/dist-packages/tensorflow/python/summary/summary.py", line 192, in histogram
    tag=tag, values=values, name=scope)
  File "/usr/local/lib/python3.5/dist-packages/tensorflow/python/ops/gen_logging_ops.py", line 188, in _histogram_summary
    "HistogramSummary", tag=tag, values=values, name=name)
  File "/usr/local/lib/python3.5/dist-packages/tensorflow/python/framework/op_def_library.py", line 787, in _apply_op_helper
    op_def=op_def)
  File "/usr/local/lib/python3.5/dist-packages/tensorflow/python/framework/ops.py", line 2956, in create_op
    op_def=op_def)
  File "/usr/local/lib/python3.5/dist-packages/tensorflow/python/framework/ops.py", line 1470, in __init__
    self._traceback = self._graph._extract_stack()  # pylint: disable=protected-access

InvalidArgumentError (see above for traceback): Nan in summary histogram for: pretrain_2/autoencoder_variables/biases2
	 [[Node: pretrain_2/autoencoder_variables/biases2 = HistogramSummary[T=DT_FLOAT, _device="/job:localhost/replica:0/task:0/device:CPU:0"](pretrain_2/autoencoder_variables/biases2/tag, autoencoder_variables/biases2/read/_3307)]]
	 [[Node: pretrain_2/xentropy_loss/mul/_3302 = _Send[T=DT_FLOAT, client_terminated=false, recv_device="/job:localhost/replica:0/task:0/device:CPU:0", send_device="/job:localhost/replica:0/task:0/device:GPU:0", send_device_incarnation=1, tensor_name="edge_48_pretrain_2/xentropy_loss/mul", _device="/job:localhost/replica:0/task:0/device:GPU:0"](pretrain_2/xentropy_loss/mul)]]

